# Generator函数

## 简介

**基本概念**

Generator 函数是 ES6 提供的一种异步编程解决方案，语法行为与传统函数完全不同。本章详细介绍 Generator 函数的语法和 API，它的异步编程应用请看《Generator 函数的异步应用》一章。

Generator 函数有多种理解角度。语法上，首先可以把它理解成，Generator 函数是一个状态机，封装了多个内部状态。

执行 Generator 函数会返回一个遍历器对象，也就是说，Generator 函数除了状态机，还是一个遍历器对象生成函数。返回的遍历器对象，可以依次遍历 Generator 函数内部的每一个状态。

形式上，Generator 函数是一个普通函数，但是有两个特征。一是，`function`关键字与函数名之间有一个星号；二是，函数体内部使用`yield`表达式，定义不同的内部状态（`yield`在英语里的意思就是“产出”）。

```javascript
function* helloWorldGenerator() {
  yield 'hello';
  yield 'world';
  return 'ending';
}

var hw = helloWorldGenerator();
```

上面代码定义了一个 Generator 函数`helloWorldGenerator`，它内部有两个`yield`表达式（`hello`和`world`），即该函数有三个状态：hello，world 和 return 语句（结束执行）。

然后，Generator 函数的调用方法与普通函数一样，也是在函数名后面加上一对圆括号。不同的是，调用 Generator 函数后，该函数并不执行，返回的也不是函数运行结果，而是一个指向内部状态的指针对象，也就是上一章介绍的遍历器对象（Iterator Object）。

下一步，必须调用遍历器对象的`next`方法，使得指针移向下一个状态。也就是说，每次调用`next`方法，内部指针就从函数头部或上一次停下来的地方开始执行，直到遇到下一个`yield`表达式（或`return`语句）为止。换言之，Generator 函数是分段执行的，`yield`表达式是暂停执行的标记，而`next`方法可以恢复执行。

```javascript
hw.next()
// { value: 'hello', done: false }

hw.next()
// { value: 'world', done: false }

hw.next()
// { value: 'ending', done: true }

hw.next()
// { value: undefined, done: true }
```

上面代码一共调用了四次`next`方法。

第一次调用，Generator 函数开始执行，直到遇到第一个`yield`表达式为止。`next`方法返回一个对象，它的`value`属性就是当前`yield`表达式的值`hello`，`done`属性的值`false`，表示遍历还没有结束。

第二次调用，Generator 函数从上次`yield`表达式停下的地方，一直执行到下一个`yield`表达式。`next`方法返回的对象的`value`属性就是当前`yield`表达式的值`world`，`done`属性的值`false`，表示遍历还没有结束。

第三次调用，Generator 函数从上次`yield`表达式停下的地方，一直执行到`return`语句（如果没有`return`语句，就执行到函数结束）。`next`方法返回的对象的`value`属性，就是紧跟在`return`语句后面的表达式的值（如果没有`return`语句，则`value`属性的值为`undefined`），`done`属性的值`true`，表示遍历已经结束。

第四次调用，此时 Generator 函数已经运行完毕，`next`方法返回对象的`value`属性为`undefined`，`done`属性为`true`。以后再调用`next`方法，返回的都是这个值。

总结一下，调用 Generator 函数，返回一个遍历器对象，代表 Generator 函数的内部指针。以后，每次调用遍历器对象的`next`方法，就会返回一个有着`value`和`done`两个属性的对象。`value`属性表示当前的内部状态的值，是`yield`表达式后面那个表达式的值；`done`属性是一个布尔值，表示是否遍历结束。

## yield 表达式

由于 Generator 函数返回的遍历器对象，只有调用`next`方法才会遍历下一个内部状态，所以其实提供了一种可以暂停执行的函数。`yield`表达式就是暂停标志。

遍历器对象的`next`方法的运行逻辑如下。

（1）遇到`yield`表达式，就暂停执行后面的操作，并将紧跟在`yield`后面的那个表达式的值，作为返回的对象的`value`属性值。

（2）下一次调用`next`方法时，再继续往下执行，直到遇到下一个`yield`表达式。

（3）如果没有再遇到新的`yield`表达式，就一直运行到函数结束，直到`return`语句为止，并将`return`语句后面的表达式的值，作为返回的对象的`value`属性值。

（4）如果该函数没有`return`语句，则返回的对象的`value`属性值为`undefined`。

需要注意的是，`yield`表达式后面的表达式，只有当调用`next`方法、内部指针指向该语句时才会执行，因此等于为 JavaScript 提供了手动的“惰性求值”（Lazy Evaluation）的语法功能。

```javascript
function* gen() {
  yield  123 + 456;
}
```

上面代码中，`yield`后面的表达式`123 + 456`，不会立即求值，只会在`next`方法将指针移到这一句时，才会求值。

`yield`表达式与`return`语句既有相似之处，也有区别。相似之处在于，都能返回紧跟在语句后面的那个表达式的值。区别在于每次遇到`yield`，函数暂停执行，下一次再从该位置继续向后执行，而`return`语句不具备位置记忆的功能。一个函数里面，只能执行一次（或者说一个）`return`语句，但是可以执行多次（或者说多个）`yield`表达式。正常函数只能返回一个值，因为只能执行一次`return`；Generator 函数可以返回一系列的值，因为可以有任意多个`yield`。从另一个角度看，也可以说 Generator 生成了一系列的值，这也就是它的名称的来历（英语中，generator 这个词是“生成器”的意思）。

另外需要注意，`yield`表达式只能用在 Generator 函数里面，用在其他地方都会报错。

```javascript
(function (){
  yield 1;
})()
// SyntaxError: Unexpected number
```

上面代码在一个普通函数中使用`yield`表达式，结果产生一个句法错误。

下面是另外一个例子。

```javascript
var arr = [1, [[2, 3], 4], [5, 6]];

var flat = function* (a) {
  a.forEach(function (item) {
    if (typeof item !== 'number') {
      yield* flat(item);
    } else {
      yield item;
    }
  });
};

for (var f of flat(arr)){
  console.log(f);
}
```

上面代码也会产生句法错误，因为`forEach`方法的参数是一个普通函数，但是在里面使用了`yield`表达式（这个函数里面还使用了`yield*`表达式，详细介绍见后文）。

另外，`yield`表达式如果用在另一个表达式之中，必须放在圆括号里面。

```javascript
function* demo() {
  console.log('Hello' + yield); // SyntaxError
  console.log('Hello' + yield 123); // SyntaxError

  console.log('Hello' + (yield)); // OK
  console.log('Hello' + (yield 123)); // OK
}
```

`yield`表达式用作函数参数或放在赋值表达式的右边，可以不加括号。

```javascript
function* demo() {
  foo(yield 'a', yield 'b'); // OK
  let input = yield; // OK
}
```

## 与 Iterator 接口的关系

上一章说过，任意一个对象的`Symbol.iterator`方法，等于该对象的遍历器生成函数，调用该函数会返回该对象的一个遍历器对象。

由于 Generator 函数就是遍历器生成函数，因此可以把 Generator 赋值给对象的`Symbol.iterator`属性，从而使得该对象具有 Iterator 接口。

```javascript
var myIterable = {};
myIterable[Symbol.iterator] = function* () {
  yield 1;
  yield 2;
  yield 3;
};

[...myIterable] // [1, 2, 3]
```

上面代码中，Generator 函数赋值给`Symbol.iterator`属性，从而使得`myIterable`对象具有了 Iterator 接口，可以被`...`运算符遍历了。

## next 方法的参数

`yield`表达式本身没有返回值，或者说总是返回`undefined`。`next`方法可以带一个参数，该参数就会被当作上一个`yield`表达式的返回值。

```javascript
function* f() {
  for(var i = 0; true; i++) {
    var reset = yield i;
    if(reset) { i = -1; }
  }
}

var g = f();

g.next() // { value: 0, done: false }
g.next() // { value: 1, done: false }
g.next(true) // { value: 0, done: false }
```

上面代码先定义了一个可以无限运行的 Generator 函数`f`，如果`next`方法没有参数，每次运行到`yield`表达式，变量`reset`的值总是`undefined`。当`next`方法带一个参数`true`时，变量`reset`就被重置为这个参数（即`true`），因此`i`会等于`-1`，下一轮循环就会从`-1`开始递增。

这个功能有很重要的语法意义。Generator 函数从暂停状态到恢复运行，它的上下文状态（context）是不变的。通过`next`方法的参数，就有办法在 Generator 函数开始运行之后，继续向函数体内部注入值。也就是说，可以在 Generator 函数运行的不同阶段，从外部向内部注入不同的值，从而调整函数行为。

再看一个例子。

```javascript
function* foo(x) {
  var y = 2 * (yield (x + 1));
  var z = yield (y / 3);
  return (x + y + z);
}

var a = foo(5);
a.next() // Object{value:6, done:false}
a.next() // Object{value:NaN, done:false}
a.next() // Object{value:NaN, done:true}

var b = foo(5);
b.next() // { value:6, done:false }
b.next(12) // { value:8, done:false }
b.next(13) // { value:42, done:true }
```

上面代码中，第二次运行`next`方法的时候不带参数，导致 y 的值等于`2 * undefined`（即`NaN`），除以 3 以后还是`NaN`，因此返回对象的`value`属性也等于`NaN`。第三次运行`Next`方法的时候不带参数，所以`z`等于`undefined`，返回对象的`value`属性等于`5 + NaN + undefined`，即`NaN`。

如果向`next`方法提供参数，返回结果就完全不一样了。上面代码第一次调用`b`的`next`方法时，返回`x+1`的值`6`；第二次调用`next`方法，将上一次`yield`表达式的值设为`12`，因此`y`等于`24`，返回`y / 3`的值`8`；第三次调用`next`方法，将上一次`yield`表达式的值设为`13`，因此`z`等于`13`，这时`x`等于`5`，`y`等于`24`，所以`return`语句的值等于`42`。

注意，由于`next`方法的参数表示上一个`yield`表达式的返回值，所以在第一次使用`next`方法时，传递参数是无效的。V8 引擎直接忽略第一次使用`next`方法时的参数，只有从第二次使用`next`方法开始，参数才是有效的。从语义上讲，第一个`next`方法用来启动遍历器对象，所以不用带有参数。

## for...of 循环

`for...of`循环可以自动遍历 Generator 函数运行时生成的`Iterator`对象，且此时不再需要调用`next`方法。

```javascript
function* foo() {
  yield 1;
  yield 2;
  yield 3;
  yield 4;
  yield 5;
  return 6;
}

for (let v of foo()) {
  console.log(v);
}
// 1 2 3 4 5
```

上面代码使用`for...of`循环，依次显示 5 个`yield`表达式的值。这里需要注意，一旦`next`方法的返回对象的`done`属性为`true`，`for...of`循环就会中止，且不包含该返回对象，所以上面代码的`return`语句返回的`6`，不包括在`for...of`循环之中。

# async函数

## 基本用法

`async`函数返回一个 Promise 对象，可以使用`then`方法添加回调函数。当函数执行的时候，一旦遇到`await`就会先返回，等到异步操作完成，再接着执行函数体内后面的语句。

下面是一个例子。

```javascript
async function getStockPriceByName(name) {
  const symbol = await getStockSymbol(name);
  const stockPrice = await getStockPrice(symbol);
  return stockPrice;
}

getStockPriceByName('goog').then(function (result) {
  console.log(result);
});
```

上面代码是一个获取股票报价的函数，函数前面的`async`关键字，表明该函数内部有异步操作。调用该函数时，会立即返回一个`Promise`对象。

下面是另一个例子，指定多少毫秒后输出一个值。

```javascript
function timeout(ms) {
  return new Promise((resolve) => {
    setTimeout(resolve, ms);
  });
}

async function asyncPrint(value, ms) {
  await timeout(ms);
  console.log(value);
}

asyncPrint('hello world', 50);
```

上面代码指定 50 毫秒以后，输出`hello world`。

async 函数有多种使用形式。

```javascript
// 函数声明
async function foo() {}

// 函数表达式
const foo = async function () {};

// 对象的方法
let obj = { async foo() {} };
obj.foo().then(...)

// Class 的方法
class Storage {
  constructor() {
    this.cachePromise = caches.open('avatars');
  }

  async getAvatar(name) {
    const cache = await this.cachePromise;
    return cache.match(`/avatars/${name}.jpg`);
  }
}

const storage = new Storage();
storage.getAvatar('jake').then(…);

// 箭头函数
const foo = async () => {};
```

## 语法

### **返回Promise对象**

`async`函数返回一个 Promise 对象。

`async`函数内部`return`语句返回的值，会成为`then`方法回调函数的参数。

```javascript
async function f() {
  return 'hello world';
}

f().then(v => console.log(v))
// "hello world"
```

上面代码中，函数`f`内部`return`命令返回的值，会被`then`方法回调函数接收到。

`async`函数内部抛出错误，会导致返回的 Promise 对象变为`reject`状态。抛出的错误对象会被`catch`方法回调函数接收到。

```javascript
async function f() {
  throw new Error('出错了');
}

f().then(
  v => console.log(v),
  e => console.log(e)
)
// Error: 出错了
```

### **Promise对象的状态变化**

`async`函数返回的 Promise 对象，必须等到内部所有`await`命令后面的 Promise 对象执行完，才会发生状态改变，除非遇到`return`语句或者抛出错误。也就是说，只有`async`函数内部的异步操作执行完，才会执行`then`方法指定的回调函数。

下面是一个例子。

```javascript
async function getTitle(url) {
  let response = await fetch(url);
  let html = await response.text();
  return html.match(/<title>([\s\S]+)<\/title>/i)[1];
}
getTitle('https://tc39.github.io/ecma262/').then(console.log)
// "ECMAScript 2017 Language Specification"
```

上面代码中，函数`getTitle`内部有三个操作：抓取网页、取出文本、匹配页面标题。只有这三个操作全部完成，才会执行`then`方法里面的`console.log`。

### **await命令**

正常情况下，`await`命令后面是一个 Promise 对象，返回该对象的结果。如果不是 Promise 对象，就直接返回对应的值。

```javascript
async function f() {
  // 等同于
  // return 123;
  return await 123;
}

f().then(v => console.log(v))
// 123
```

上面代码中，`await`命令的参数是数值`123`，这时等同于`return 123`。

另一种情况是，`await`命令后面是一个`thenable`对象（即定义了`then`方法的对象），那么`await`会将其等同于 Promise 对象。

```javascript
class Sleep {
  constructor(timeout) {
    this.timeout = timeout;
  }
  then(resolve, reject) {
    const startTime = Date.now();
    setTimeout(
      () => resolve(Date.now() - startTime),
      this.timeout
    );
  }
}

(async () => {
  const sleepTime = await new Sleep(1000);
  console.log(sleepTime);
})();
// 1000
```

上面代码中，`await`命令后面是一个`Sleep`对象的实例。这个实例不是 Promise 对象，但是因为定义了`then`方法，`await`会将其视为`Promise`处理。

`await`命令后面的 Promise 对象如果变为`reject`状态，则`reject`的参数会被`catch`方法的回调函数接收到。

```javascript
async function f() {
  await Promise.reject('出错了');
}

f()
.then(v => console.log(v))
.catch(e => console.log(e))
// 出错了
```

注意，上面代码中，`await`语句前面没有`return`，但是`reject`方法的参数依然传入了`catch`方法的回调函数。这里如果在`await`前面加上`return`，效果是一样的。

任何一个`await`语句后面的 Promise 对象变为`reject`状态，那么整个`async`函数都会中断执行。

```javascript
async function f() {
  await Promise.reject('出错了');
  await Promise.resolve('hello world'); // 不会执行
}
```

上面代码中，第二个`await`语句是不会执行的，因为第一个`await`语句状态变成了`reject`。

有时，我们希望即使前一个异步操作失败，也不要中断后面的异步操作。这时可以将第一个`await`放在`try...catch`结构里面，这样不管这个异步操作是否成功，第二个`await`都会执行。

```javascript
async function f() {
  try {
    await Promise.reject('出错了');
  } catch(e) {
  }
  return await Promise.resolve('hello world');
}

f()
.then(v => console.log(v))
// hello world
```

另一种方法是`await`后面的 Promise 对象再跟一个`catch`方法，处理前面可能出现的错误。

```javascript
async function f() {
  await Promise.reject('出错了')
    .catch(e => console.log(e));
  return await Promise.resolve('hello world');
}

f()
.then(v => console.log(v))
// 出错了
// hello world
```

### **错误处理**

如果`await`后面的异步操作出错，那么等同于`async`函数返回的 Promise 对象被`reject`。

```javascript
async function f() {
  await new Promise(function (resolve, reject) {
    throw new Error('出错了');
  });
}

f()
.then(v => console.log(v))
.catch(e => console.log(e))
// Error：出错了
```

上面代码中，`async`函数`f`执行后，`await`后面的 Promise 对象会抛出一个错误对象，导致`catch`方法的回调函数被调用，它的参数就是抛出的错误对象。具体的执行机制，可以参考后文的“async 函数的实现原理”。

防止出错的方法，也是将其放在`try...catch`代码块之中。

```javascript
async function f() {
  try {
    await new Promise(function (resolve, reject) {
      throw new Error('出错了');
    });
  } catch(e) {
  }
  return await('hello world');
}
```

如果有多个`await`命令，可以统一放在`try...catch`结构中。

```javascript
async function main() {
  try {
    const val1 = await firstStep();
    const val2 = await secondStep(val1);
    const val3 = await thirdStep(val1, val2);

    console.log('Final: ', val3);
  }
  catch (err) {
    console.error(err);
  }
}
```

# class的基本语法



